{"name": "test_something", "status": "broken", "statusDetails": {"message": "AttributeError: 'TestCase' object has no attribute 'data'", "trace": "self = <TestCases.test.TestCase object at 0x000001D138A52888>\n\n    def test_something(self):\n        print('执行测试')\n        # 获取前置方法中产生的数据\n        # 从全局变量中获取\n        # print(EnvData.data)\n        # 从当前用例的类属性中获取\n        # print(self.__class__.res1)\n        # 如果当前用例对象没有同名对象属性，也可以直接从对象属性中获取\n>       print(self.data)\nE       AttributeError: 'TestCase' object has no attribute 'data'\n\ntest.py:34: AttributeError"}, "start": 1647351574391, "stop": 1647351574391, "uuid": "1ea2784e-519e-4d5b-b9d8-1388a0a0343f", "historyId": "39a634f11d7b84a6209b18be84273ba0", "testCaseId": "5c116e581817ad4319fbae74ed49d15d", "fullName": "TestCases.test.TestCase#test_something", "labels": [{"name": "parentSuite", "value": "TestCases"}, {"name": "suite", "value": "test"}, {"name": "subSuite", "value": "TestCase"}, {"name": "host", "value": "DESKTOP-76566J4"}, {"name": "thread", "value": "4260-MainThread"}, {"name": "framework", "value": "pytest"}, {"name": "language", "value": "cpython3"}, {"name": "package", "value": "TestCases.test"}]}